<?xml version="1.0"?>
<robot name="AROV" xmlns:xacro="http://ros.org/wiki/xacro">
    <!-- Physical Constants -->
    <xacro:property name="base_width"   value="0.33"/>
    <xacro:property name="base_length"  value="0.455"/>
    <xacro:property name="base_height"  value="0.09"/>
    <xacro:property name="thrust_rad"   value="0.045"/>
    <xacro:property name="thrust_width" value="0.09"/>
    <xacro:property name="thrust_xoff"  value="0.08"/>
    <xacro:property name="thrust_yoff"  value="0.14"/>
    <xacro:property name="thrust_zoff"  value="-0.08"/>

    <!-- AROV Base -->
    <link name="arov/base_link">
        <visual>
            <geometry>
                <box size="${base_length} ${base_width} ${base_height}"/>
            </geometry>
            <material name="Blue">
                <color rgba="0.3 0.66 0.94 1.0"/>
            </material>
        </visual>
    </link>

    <!-- AROV Footprint -->
    <link name="arov/base_footprint"/>
    <joint name="arov/base_joint" type="fixed">
        <parent link="arov/base_link"/>
        <child link="arov/base_footprint"/>
        <origin xyz="0.0 0.0 0.0" rpy="0.0 0.0 0.0"/>
    </joint>

    <!-- Thrusters -->
    <xacro:macro name="thruster" params="id x_reflect y_reflect">
        <link name="arov/thruster_${id}_link">
            <visual>
                <origin xyz="0.0 0.0 0.0" rpy="${pi/2} 0 0"/>
                <geometry>
                    <cylinder radius="${thrust_rad}" length="${thrust_width}"/>
                </geometry>
                <material name="Black">
                    <color rgba="1.0 1.0 1.0 1.0"/>
                </material>
            </visual>
        </link>

        <joint name="arov/thruster_${id}" type="continuous">
            <parent link="arov/base_link"/>
            <child link="arov/thruster_${id}_link"/>
            <origin xyz="${x_reflect*thrust_xoff} ${y_reflect*thrust_yoff} ${thrust_zoff}" rpy="0 0 ${-x_reflect*y_reflect*pi/4}"/>
            <axis xyz="1 1 0"/>
        </joint>
    </xacro:macro>

    <xacro:thruster id="fr" x_reflect="1" y_reflect="1"/>
    <xacro:thruster id="fl" x_reflect="-1" y_reflect="1"/>
    <xacro:thruster id="bl" x_reflect="-1" y_reflect="-1"/>
    <xacro:thruster id="br" x_reflect="1" y_reflect="-1"/>
</robot>
