<?xml version="1.0"?>
<robot name="ASV" xmlns:xacro="http://ros.org/wiki/xacro">
    <!-- Physical Constants -->
    <xacro:property name="base_width"   value="0.38"/>
    <xacro:property name="base_length"  value="0.48"/>
    <xacro:property name="base_height"  value="0.185"/>
    <xacro:property name="pont_width"   value="0.16"/>
    <xacro:property name="pont_length"  value="0.96"/>
    <xacro:property name="pont_height"  value="0.12"/>
    <xacro:property name="pont_yoff"    value="0.16"/>
    <xacro:property name="pont_zoff"    value="-0.135"/>
    <xacro:property name="bar_width"    value="0.025"/>
    <xacro:property name="bar_height"   value="0.16"/>
    <xacro:property name="bar_xoff"     value="0.3"/>
    <xacro:property name="bar_yoff"     value="0.06"/>
    <xacro:property name="bar_zoff"     value="-0.055"/>
    <xacro:property name="thrust_rad"   value="0.045"/>
    <xacro:property name="thrust_width" value="0.09"/>

    <!-- ASV Base -->
    <link name="asv/base_link">
        <visual>
            <geometry>
                <box size="${base_length} ${base_width} ${base_height}"/>
            </geometry>
            <material name="Orange">
                <color rgba="0.9 0.45 0.0 1.0"/>
            </material>
        </visual>
    </link>

    <!-- ASV Footprint -->
    <link name="asv/base_footprint"/>
    <joint name="asv/base_joint" type="fixed">
        <parent link="asv/base_link"/>
        <child link="asv/base_footprint"/>
        <origin xyz="0.0 0.0 0.0" rpy="0.0 0.0 0.0"/>
    </joint>

    <!-- Pontoons -->
    <xacro:macro name="pontoon" params="id y_reflect">
        <link name="asv/pontoon_${id}_link">
            <visual>
                <origin xyz="0.0 0.0 0.0" rpy="0.0 0.0 0.0"/>
                <geometry>
                    <box size="${pont_length} ${pont_width} ${pont_height}"/>
                </geometry>
                <material name="Grey">
                    <color rgba="0.85 0.85 0.85 1.0"/>
                </material>
            </visual>
        </link>

        <joint name="asv/pontoon_${id}" type="fixed">
            <parent link="asv/base_link"/>
            <child link="asv/pontoon_${id}_link"/>
            <origin xyz="0.0 ${y_reflect*pont_yoff} ${pont_zoff}" rpy="0.0 0.0 0.0"/>
        </joint>
    </xacro:macro>

    <xacro:pontoon id="r" y_reflect="1"/>
    <xacro:pontoon id="l" y_reflect="-1"/>

    <!-- Thrusters -->
    <xacro:macro name="thruster" params="id y_reflect">
        <link name="asv/thruster_${id}_link">
            <visual>
                <origin xyz="0.0 0.0 0.0" rpy="${pi/2} 0.0 0.0"/>
                <geometry>
                    <cylinder radius="${thrust_rad}" length="${thrust_width}"/>
                </geometry>
                <material name="Black">
                    <color rgba="1.0 1.0 1.0 1.0"/>
                </material>
            </visual>
        </link>

        <joint name="asv/thruster_${id}" type="continuous">
            <parent link="asv/base_link"/>
            <child link="asv/thruster_${id}_link"/>
            <origin xyz="${bar_xoff} ${y_reflect*bar_yoff} ${bar_zoff-bar_height-thrust_rad}" rpy="0 0 0"/>
            <axis xyz="1 0 0"/>
        </joint>
    </xacro:macro>

    <xacro:thruster id="r" y_reflect="1"/>
    <xacro:thruster id="l" y_reflect="1"/>
</robot>
